<?xml version="1.0" ?>
<sdf version="1.5">
  <model name="car">
    <link name="chassis">
      <pose>0 0 0.3 0 0 0</pose>
      <collision name="collision">
        <geometry>
          <box>
            <size>2.0 1.0 0.2</size>
          </box>
        </geometry>
      </collision>
      <visual name="visual">
        <geometry>
          <box>
            <size>2.0 1.0 0.2</size>
          </box>
        </geometry>
        <material>
          <script>
            <uri>file://media/materials/scripts/gazebo.material</uri>
            <name>Gazebo/Green</name>
          </script>
        </material>
      </visual>
    </link>
    <link name="front_left_wheel">
      <pose>0.8 0.6 0.3 0 1.5707 1.5707</pose>
      <collision name="collision">
        <geometry>
          <cylinder>
            <radius>0.3</radius>
            <length>0.1</length>
          </cylinder>
        </geometry>
        <surface>
          <friction>
            <ode>
              <mu>1</mu>
              <mu2>1</mu2>
              <slip1>0</slip1>
              <slip2>0</slip2>
            </ode>
          </friction>
        </surface>

      </collision>
      <visual name="visual">
        <geometry>
          <cylinder>
            <radius>0.3</radius>
            <length>0.1</length>
          </cylinder>
        </geometry>
        <material>
          <script>
            <uri>file://media/materials/scripts/gazebo.material</uri>
            <name>Gazebo/Black</name>
          </script>
        </material>
      </visual>
    </link>
    <link name="front_right_wheel">
      <pose>0.8 -0.6 0.3 0 1.5707 1.5707</pose>
      <collision name="collision">
        <geometry>
          <cylinder>
            <radius>0.3</radius>
            <length>0.1</length>
          </cylinder>
        </geometry>
        <surface>
          <friction>
            <ode>
              <mu>1</mu>
              <mu2>1</mu2>
              <slip1>0</slip1>
              <slip2>0</slip2>
            </ode>
          </friction>
        </surface>

      </collision>
      <visual name="visual">
        <geometry>
          <cylinder>
            <radius>0.3</radius>
            <length>0.1</length>
          </cylinder>
        </geometry>
        <material>
          <script>
            <uri>file://media/materials/scripts/gazebo.material</uri>
            <name>Gazebo/Black</name>
          </script>
        </material>
      </visual>
    </link>
    <link name="back_right_wheel">
      <pose>-0.8 -0.6 0.3 0 1.5707 1.5707</pose>
      <collision name="collision">
        <geometry>
          <cylinder>
            <radius>0.3</radius>
            <length>0.1</length>
          </cylinder>
        </geometry>
        <surface>
          <friction>
            <ode>
              <mu>1</mu>
              <mu2>1</mu2>
              <slip1>0</slip1>
              <slip2>0</slip2>
            </ode>
          </friction>
        </surface>

      </collision>
      <visual name="visual">
        <geometry>
          <cylinder>
            <radius>0.3</radius>
            <length>0.1</length>
          </cylinder>
        </geometry>
        <material>
          <script>
            <uri>file://media/materials/scripts/gazebo.material</uri>
            <name>Gazebo/Black</name>
          </script>
        </material>
      </visual>
    </link>
    <link name="back_left_wheel">
      <pose>-0.8 0.6 0.3 0 1.5707 1.5707</pose>
      <collision name="collision">
        <geometry>
          <cylinder>
            <radius>0.3</radius>
            <length>0.1</length>
          </cylinder>
        </geometry>
        <surface>
          <friction>
            <ode>
              <mu>1</mu>
              <mu2>1</mu2>
              <slip1>0</slip1>
              <slip2>0</slip2>
            </ode>
          </friction>
        </surface>
      </collision>
      <visual name="visual">
        <geometry>
          <cylinder>
            <radius>0.3</radius>
            <length>0.1</length>
          </cylinder>
        </geometry>
        <material>
          <script>
            <uri>file://media/materials/scripts/gazebo.material</uri>
            <name>Gazebo/Black</name>
          </script>
        </material>
      </visual>
    </link>
    <link name="gas_pedal">
      <pose>0.3 0.1 0.5 0 0 0</pose>
      <collision name="collision">
        <geometry>
          <box>
            <size>0.1 0.1 0.1</size>
          </box>
        </geometry>
      </collision>
      <visual name="visual">
        <geometry>
          <box>
            <size>0.1 0.1 0.1</size>
          </box>
        </geometry>
        <material>
          <script>
            <uri>file://media/materials/scripts/gazebo.material</uri>
            <name>Gazebo/Red</name>
          </script>
        </material>
      </visual>
    </link>
    <link name="brake_pedal">
      <pose>0.3 0.25 0.5 0 0 0</pose>
      <collision name="collision">
        <geometry>
          <box>
            <size>0.1 0.1 0.1</size>
          </box>
        </geometry>
      </collision>
      <visual name="visual">
        <geometry>
          <box>
            <size>0.1 0.1 0.1</size>
          </box>
        </geometry>
        <material>
          <script>
            <uri>file://media/materials/scripts/gazebo.material</uri>
            <name>Gazebo/Blue</name>
          </script>
        </material>
      </visual>
    </link>
    <link name="steering_wheel">
      <pose>0.3 0.2 1.0 0 1.5707 0</pose>
      <collision name="collision">
        <geometry>
          <cylinder>
            <radius>0.1</radius>
            <length>0.01</length>
          </cylinder>
        </geometry>
      </collision>
      <visual name="visual">
        <geometry>
          <cylinder>
            <radius>0.1</radius>
            <length>0.01</length>
          </cylinder>
        </geometry>
        <material>
          <script>
            <uri>file://media/materials/scripts/gazebo.material</uri>
            <name>Gazebo/Blue</name>
          </script>
        </material>
      </visual>
    </link>
    <joint type="prismatic" name="gas_joint">
      <parent>chassis</parent>
      <child>gas_pedal</child>
      <axis>
        <xyz>1 0 0</xyz>
        <limit>
          <lower>0</lower>
          <upper>0.2</upper>
        </limit>
        <use_parent_model_frame>true</use_parent_model_frame>
      </axis>
    </joint>
    <joint type="prismatic" name="brake_joint">
      <parent>chassis</parent>
      <child>brake_pedal</child>
      <axis>
        <xyz>1 0 0</xyz>
        <limit>
          <lower>0</lower>
          <upper>0.2</upper>
        </limit>
        <use_parent_model_frame>true</use_parent_model_frame>
      </axis>
    </joint>
    <joint type="revolute" name="steering_joint">
      <parent>chassis</parent>
      <child>steering_wheel</child>
      <axis>
        <xyz>1 0 0</xyz>
        <limit>
          <lower>-7.853</lower>
          <upper>7.853</upper>
        </limit>
        <use_parent_model_frame>true</use_parent_model_frame>
      </axis>
    </joint>
    <joint type="revolute" name="front_left_joint">
      <parent>chassis</parent>
      <child>front_left_wheel</child>
      <axis>
        <xyz>0 1 0</xyz>
        <use_parent_model_frame>true</use_parent_model_frame>
      </axis>
    </joint>
    <joint type="revolute" name="front_right_joint">
      <parent>chassis</parent>
      <child>front_right_wheel</child>
      <axis>
        <xyz>0 1 0</xyz>
        <use_parent_model_frame>true</use_parent_model_frame>
      </axis>
    </joint>
    <joint type="revolute" name="back_right_joint">
      <parent>chassis</parent>
      <child>back_right_wheel</child>
      <axis>
        <xyz>0 1 0</xyz>
        <use_parent_model_frame>true</use_parent_model_frame>
      </axis>
    </joint>
    <joint type="revolute" name="back_left_joint">
      <parent>chassis</parent>
      <child>back_left_wheel</child>
      <axis>
        <xyz>0 1 0</xyz>
        <use_parent_model_frame>true</use_parent_model_frame>
      </axis>
    </joint>
  <plugin name="skid_steer_drive_controller" filename="libgazebo_ros_skid_steer_drive.so">
    <updateRate>100.0</updateRate>
    <robotNamespace>/</robotNamespace>
    <leftFrontJoint>front_left_joint</leftFrontJoint>
    <rightFrontJoint>front_right_joint</rightFrontJoint>
    <leftRearJoint>back_left_joint</leftRearJoint>
    <rightRearJoint>back_right_joint</rightRearJoint>
    <wheelSeparation>0.4</wheelSeparation>
    <wheelDiameter>0.215</wheelDiameter>
    <robotBaseFrame>chassis</robotBaseFrame>
    <torque>20</torque>
    <commandTopic>cmd_vel_2</commandTopic>
    <broadcastTF>false</broadcastTF>
  </plugin>
<!--
    <plugin filename="libVehiclePlugin.so" name="vehicle">
      <front_left>front_left_joint</front_left>
      <front_right>front_right_joint</front_right>
      <back_left>back_left_joint</back_left>
      <back_right>back_right_joint</back_right>
      <gas>gas_joint</gas>
      <brake>brake_joint</brake>
      <steering>steering_joint</steering>
      <front_power>10</front_power>
      <rear_power>10</rear_power>
      <tire_angle_range>0.5</tire_angle_range>
      <max_speed>10</max_speed>
      <aero_load>0.1</aero_load>
    </plugin>
-->
  </model>
</sdf>
